INFO 2024-02-06 10:29:10,389 views Affichage de la liste des lettings.
WARNING 2024-02-06 10:29:10,459 log Not Found: /une_url_inexistante/
ERROR 2024-02-06 10:29:10,484 views Erreur interne du serveur déclenchée.
ERROR 2024-02-06 10:29:10,540 log Internal Server Error: /test-500/
Traceback (most recent call last):
  File "/home/walid/Bureau/oc_p13/venv/lib/python3.11/site-packages/django/core/handlers/exception.py", line 55, in inner
    response = get_response(request)
               ^^^^^^^^^^^^^^^^^^^^^
  File "/home/walid/Bureau/oc_p13/venv/lib/python3.11/site-packages/django/core/handlers/base.py", line 197, in _get_response
    response = wrapped_callback(request, *callback_args, **callback_kwargs)
               ^^^^^^^^^^^^^^^^^^^^^^^^^^^^^^^^^^^^^^^^^^^^^^^^^^^^^^^^^^^^
  File "/home/walid/Bureau/oc_p13/venv/lib/python3.11/site-packages/sentry_sdk/integrations/django/views.py", line 84, in sentry_wrapped_callback
    return callback(request, *args, **kwargs)
           ^^^^^^^^^^^^^^^^^^^^^^^^^^^^^^^^^^
  File "/home/walid/Images/test_oc_p13/test_oc_p13/oc_lettings_site/views.py", line 57, in test_500
    raise ValueError("Test d'erreur 500")
ValueError: Test d'erreur 500
INFO 2024-02-06 10:29:10,566 views Affichage de la page d'accueil.
INFO 2024-02-06 10:29:10,591 views Affichage de la page d'accueil.
WARNING 2024-02-06 10:29:10,617 log Not Found: /chemin_inexistant/
ERROR 2024-02-06 10:29:10,642 views Erreur interne du serveur déclenchée.
ERROR 2024-02-06 10:29:10,664 log Internal Server Error: /test-500/
Traceback (most recent call last):
  File "/home/walid/Bureau/oc_p13/venv/lib/python3.11/site-packages/django/core/handlers/exception.py", line 55, in inner
    response = get_response(request)
               ^^^^^^^^^^^^^^^^^^^^^
  File "/home/walid/Bureau/oc_p13/venv/lib/python3.11/site-packages/django/core/handlers/base.py", line 197, in _get_response
    response = wrapped_callback(request, *callback_args, **callback_kwargs)
               ^^^^^^^^^^^^^^^^^^^^^^^^^^^^^^^^^^^^^^^^^^^^^^^^^^^^^^^^^^^^
  File "/home/walid/Bureau/oc_p13/venv/lib/python3.11/site-packages/sentry_sdk/integrations/django/views.py", line 84, in sentry_wrapped_callback
    return callback(request, *args, **kwargs)
           ^^^^^^^^^^^^^^^^^^^^^^^^^^^^^^^^^^
  File "/home/walid/Images/test_oc_p13/test_oc_p13/oc_lettings_site/views.py", line 57, in test_500
    raise ValueError("Test d'erreur 500")
ValueError: Test d'erreur 500
INFO 2024-02-06 10:29:11,047 views Quelque chose s'est produit avec l'utilisateur : testuser
INFO 2024-02-06 10:29:11,787 views Quelque chose s'est produit avec l'utilisateur : testuser
INFO 2024-02-06 10:29:14,641 views Affichage de la liste des profils.
INFO 2024-02-06 10:29:14,670 views Affichage de la liste des profils.
INFO 2024-02-06 10:29:14,699 views Affichage de la liste des profils.
INFO 2024-02-06 10:29:15,108 views Quelque chose s'est produit avec l'utilisateur : testuser
INFO 2024-02-06 10:29:15,134 views Quelque chose s'est produit avec l'utilisateur : testuser
INFO 2024-02-06 10:29:15,161 views Quelque chose s'est produit avec l'utilisateur : testuser
INFO 2024-02-06 10:36:25,792 views Affichage de la liste des lettings.
WARNING 2024-02-06 10:36:25,860 log Not Found: /une_url_inexistante/
ERROR 2024-02-06 10:36:25,884 views Erreur interne du serveur déclenchée.
ERROR 2024-02-06 10:36:25,940 log Internal Server Error: /test-500/
Traceback (most recent call last):
  File "/home/walid/Bureau/oc_p13/venv/lib/python3.11/site-packages/django/core/handlers/exception.py", line 55, in inner
    response = get_response(request)
               ^^^^^^^^^^^^^^^^^^^^^
  File "/home/walid/Bureau/oc_p13/venv/lib/python3.11/site-packages/django/core/handlers/base.py", line 197, in _get_response
    response = wrapped_callback(request, *callback_args, **callback_kwargs)
               ^^^^^^^^^^^^^^^^^^^^^^^^^^^^^^^^^^^^^^^^^^^^^^^^^^^^^^^^^^^^
  File "/home/walid/Bureau/oc_p13/venv/lib/python3.11/site-packages/sentry_sdk/integrations/django/views.py", line 84, in sentry_wrapped_callback
    return callback(request, *args, **kwargs)
           ^^^^^^^^^^^^^^^^^^^^^^^^^^^^^^^^^^
  File "/home/walid/Images/TEST-OC-P13/test_oc_p13/oc_lettings_site/views.py", line 57, in test_500
    raise ValueError("Test d'erreur 500")
ValueError: Test d'erreur 500
INFO 2024-02-06 10:36:25,967 views Affichage de la page d'accueil.
INFO 2024-02-06 10:36:25,992 views Affichage de la page d'accueil.
WARNING 2024-02-06 10:36:26,018 log Not Found: /chemin_inexistant/
ERROR 2024-02-06 10:36:26,044 views Erreur interne du serveur déclenchée.
ERROR 2024-02-06 10:36:26,066 log Internal Server Error: /test-500/
Traceback (most recent call last):
  File "/home/walid/Bureau/oc_p13/venv/lib/python3.11/site-packages/django/core/handlers/exception.py", line 55, in inner
    response = get_response(request)
               ^^^^^^^^^^^^^^^^^^^^^
  File "/home/walid/Bureau/oc_p13/venv/lib/python3.11/site-packages/django/core/handlers/base.py", line 197, in _get_response
    response = wrapped_callback(request, *callback_args, **callback_kwargs)
               ^^^^^^^^^^^^^^^^^^^^^^^^^^^^^^^^^^^^^^^^^^^^^^^^^^^^^^^^^^^^
  File "/home/walid/Bureau/oc_p13/venv/lib/python3.11/site-packages/sentry_sdk/integrations/django/views.py", line 84, in sentry_wrapped_callback
    return callback(request, *args, **kwargs)
           ^^^^^^^^^^^^^^^^^^^^^^^^^^^^^^^^^^
  File "/home/walid/Images/TEST-OC-P13/test_oc_p13/oc_lettings_site/views.py", line 57, in test_500
    raise ValueError("Test d'erreur 500")
ValueError: Test d'erreur 500
INFO 2024-02-06 10:36:26,449 views Quelque chose s'est produit avec l'utilisateur : testuser
INFO 2024-02-06 10:36:27,182 views Quelque chose s'est produit avec l'utilisateur : testuser
INFO 2024-02-06 10:36:30,044 views Affichage de la liste des profils.
INFO 2024-02-06 10:36:30,072 views Affichage de la liste des profils.
INFO 2024-02-06 10:36:30,108 views Affichage de la liste des profils.
INFO 2024-02-06 10:36:30,518 views Quelque chose s'est produit avec l'utilisateur : testuser
INFO 2024-02-06 10:36:30,543 views Quelque chose s'est produit avec l'utilisateur : testuser
INFO 2024-02-06 10:36:30,569 views Quelque chose s'est produit avec l'utilisateur : testuser
INFO 2024-02-06 10:42:45,113 views Affichage de la page d'accueil.
INFO 2024-02-06 10:42:47,082 views Affichage de la liste des profils.
INFO 2024-02-06 10:56:48,965 views Affichage de la liste des lettings.
WARNING 2024-02-06 10:56:49,034 log Not Found: /une_url_inexistante/
ERROR 2024-02-06 10:56:49,059 views Erreur interne du serveur déclenchée.
ERROR 2024-02-06 10:56:49,116 log Internal Server Error: /test-500/
Traceback (most recent call last):
  File "/home/walid/Bureau/oc_p13/venv/lib/python3.11/site-packages/django/core/handlers/exception.py", line 55, in inner
    response = get_response(request)
               ^^^^^^^^^^^^^^^^^^^^^
  File "/home/walid/Bureau/oc_p13/venv/lib/python3.11/site-packages/django/core/handlers/base.py", line 197, in _get_response
    response = wrapped_callback(request, *callback_args, **callback_kwargs)
               ^^^^^^^^^^^^^^^^^^^^^^^^^^^^^^^^^^^^^^^^^^^^^^^^^^^^^^^^^^^^
  File "/home/walid/Bureau/oc_p13/venv/lib/python3.11/site-packages/sentry_sdk/integrations/django/views.py", line 84, in sentry_wrapped_callback
    return callback(request, *args, **kwargs)
           ^^^^^^^^^^^^^^^^^^^^^^^^^^^^^^^^^^
  File "/home/walid/Images/TEST-OC-P13/test_oc_p13/oc_lettings_site/views.py", line 57, in test_500
    raise ValueError("Test d'erreur 500")
ValueError: Test d'erreur 500
INFO 2024-02-06 10:56:49,143 views Affichage de la page d'accueil.
INFO 2024-02-06 10:56:49,169 views Affichage de la page d'accueil.
WARNING 2024-02-06 10:56:49,196 log Not Found: /chemin_inexistant/
ERROR 2024-02-06 10:56:49,222 views Erreur interne du serveur déclenchée.
ERROR 2024-02-06 10:56:49,246 log Internal Server Error: /test-500/
Traceback (most recent call last):
  File "/home/walid/Bureau/oc_p13/venv/lib/python3.11/site-packages/django/core/handlers/exception.py", line 55, in inner
    response = get_response(request)
               ^^^^^^^^^^^^^^^^^^^^^
  File "/home/walid/Bureau/oc_p13/venv/lib/python3.11/site-packages/django/core/handlers/base.py", line 197, in _get_response
    response = wrapped_callback(request, *callback_args, **callback_kwargs)
               ^^^^^^^^^^^^^^^^^^^^^^^^^^^^^^^^^^^^^^^^^^^^^^^^^^^^^^^^^^^^
  File "/home/walid/Bureau/oc_p13/venv/lib/python3.11/site-packages/sentry_sdk/integrations/django/views.py", line 84, in sentry_wrapped_callback
    return callback(request, *args, **kwargs)
           ^^^^^^^^^^^^^^^^^^^^^^^^^^^^^^^^^^
  File "/home/walid/Images/TEST-OC-P13/test_oc_p13/oc_lettings_site/views.py", line 57, in test_500
    raise ValueError("Test d'erreur 500")
ValueError: Test d'erreur 500
INFO 2024-02-06 10:56:49,633 views Quelque chose s'est produit avec l'utilisateur : testuser
INFO 2024-02-06 10:56:50,381 views Quelque chose s'est produit avec l'utilisateur : testuser
INFO 2024-02-06 10:56:53,300 views Affichage de la liste des profils.
INFO 2024-02-06 10:56:53,329 views Affichage de la liste des profils.
INFO 2024-02-06 10:56:53,357 views Affichage de la liste des profils.
INFO 2024-02-06 10:56:53,773 views Quelque chose s'est produit avec l'utilisateur : testuser
INFO 2024-02-06 10:56:53,799 views Quelque chose s'est produit avec l'utilisateur : testuser
INFO 2024-02-06 10:56:53,825 views Quelque chose s'est produit avec l'utilisateur : testuser
INFO 2024-02-06 11:05:32,979 views Affichage de la liste des lettings.
WARNING 2024-02-06 11:05:33,047 log Not Found: /une_url_inexistante/
ERROR 2024-02-06 11:05:33,072 views Erreur interne du serveur déclenchée.
ERROR 2024-02-06 11:05:33,128 log Internal Server Error: /test-500/
Traceback (most recent call last):
  File "/home/walid/Bureau/oc_p13/venv/lib/python3.11/site-packages/django/core/handlers/exception.py", line 55, in inner
    response = get_response(request)
               ^^^^^^^^^^^^^^^^^^^^^
  File "/home/walid/Bureau/oc_p13/venv/lib/python3.11/site-packages/django/core/handlers/base.py", line 197, in _get_response
    response = wrapped_callback(request, *callback_args, **callback_kwargs)
               ^^^^^^^^^^^^^^^^^^^^^^^^^^^^^^^^^^^^^^^^^^^^^^^^^^^^^^^^^^^^
  File "/home/walid/Bureau/oc_p13/venv/lib/python3.11/site-packages/sentry_sdk/integrations/django/views.py", line 84, in sentry_wrapped_callback
    return callback(request, *args, **kwargs)
           ^^^^^^^^^^^^^^^^^^^^^^^^^^^^^^^^^^
  File "/home/walid/Images/TEST-OC-P13/test_oc_p13/oc_lettings_site/views.py", line 57, in test_500
    raise ValueError("Test d'erreur 500")
ValueError: Test d'erreur 500
INFO 2024-02-06 11:05:33,154 views Affichage de la page d'accueil.
INFO 2024-02-06 11:05:33,180 views Affichage de la page d'accueil.
WARNING 2024-02-06 11:05:33,205 log Not Found: /chemin_inexistant/
ERROR 2024-02-06 11:05:33,231 views Erreur interne du serveur déclenchée.
ERROR 2024-02-06 11:05:33,253 log Internal Server Error: /test-500/
Traceback (most recent call last):
  File "/home/walid/Bureau/oc_p13/venv/lib/python3.11/site-packages/django/core/handlers/exception.py", line 55, in inner
    response = get_response(request)
               ^^^^^^^^^^^^^^^^^^^^^
  File "/home/walid/Bureau/oc_p13/venv/lib/python3.11/site-packages/django/core/handlers/base.py", line 197, in _get_response
    response = wrapped_callback(request, *callback_args, **callback_kwargs)
               ^^^^^^^^^^^^^^^^^^^^^^^^^^^^^^^^^^^^^^^^^^^^^^^^^^^^^^^^^^^^
  File "/home/walid/Bureau/oc_p13/venv/lib/python3.11/site-packages/sentry_sdk/integrations/django/views.py", line 84, in sentry_wrapped_callback
    return callback(request, *args, **kwargs)
           ^^^^^^^^^^^^^^^^^^^^^^^^^^^^^^^^^^
  File "/home/walid/Images/TEST-OC-P13/test_oc_p13/oc_lettings_site/views.py", line 57, in test_500
    raise ValueError("Test d'erreur 500")
ValueError: Test d'erreur 500
INFO 2024-02-06 11:05:33,640 views Quelque chose s'est produit avec l'utilisateur : testuser
INFO 2024-02-06 11:05:34,380 views Quelque chose s'est produit avec l'utilisateur : testuser
INFO 2024-02-06 11:05:37,263 views Affichage de la liste des profils.
INFO 2024-02-06 11:05:37,291 views Affichage de la liste des profils.
INFO 2024-02-06 11:05:37,319 views Affichage de la liste des profils.
INFO 2024-02-06 11:05:37,733 views Quelque chose s'est produit avec l'utilisateur : testuser
INFO 2024-02-06 11:05:37,759 views Quelque chose s'est produit avec l'utilisateur : testuser
INFO 2024-02-06 11:05:37,785 views Quelque chose s'est produit avec l'utilisateur : testuser
INFO 2024-02-06 11:15:47,661 views Affichage de la page d'accueil.
ERROR 2024-02-06 11:16:10,808 log Internal Server Error: /sentry-debug/
Traceback (most recent call last):
  File "/home/walid/Bureau/oc_p13/venv/lib/python3.11/site-packages/django/core/handlers/exception.py", line 55, in inner
    response = get_response(request)
               ^^^^^^^^^^^^^^^^^^^^^
  File "/home/walid/Bureau/oc_p13/venv/lib/python3.11/site-packages/django/core/handlers/base.py", line 197, in _get_response
    response = wrapped_callback(request, *callback_args, **callback_kwargs)
               ^^^^^^^^^^^^^^^^^^^^^^^^^^^^^^^^^^^^^^^^^^^^^^^^^^^^^^^^^^^^
  File "/home/walid/Bureau/oc_p13/venv/lib/python3.11/site-packages/sentry_sdk/integrations/django/views.py", line 84, in sentry_wrapped_callback
    return callback(request, *args, **kwargs)
           ^^^^^^^^^^^^^^^^^^^^^^^^^^^^^^^^^^
  File "/home/walid/Images/TEST-OC-P13/test_oc_p13/oc_lettings_site/urls.py", line 16, in trigger_error
    division_by_zero = 1 / 0
                       ~~^~~
ZeroDivisionError: division by zero
ERROR 2024-02-06 11:16:10,809 basehttp "GET /sentry-debug/ HTTP/1.1" 500 3421
INFO 2024-02-06 11:19:29,584 views Affichage de la liste des lettings.
WARNING 2024-02-06 11:19:29,657 log Not Found: /une_url_inexistante/
ERROR 2024-02-06 11:19:29,682 views Erreur interne du serveur déclenchée.
ERROR 2024-02-06 11:19:29,733 log Internal Server Error: /test-500/
Traceback (most recent call last):
  File "/home/walid/Bureau/oc_p13/venv/lib/python3.11/site-packages/django/core/handlers/exception.py", line 55, in inner
    response = get_response(request)
               ^^^^^^^^^^^^^^^^^^^^^
  File "/home/walid/Bureau/oc_p13/venv/lib/python3.11/site-packages/django/core/handlers/base.py", line 197, in _get_response
    response = wrapped_callback(request, *callback_args, **callback_kwargs)
               ^^^^^^^^^^^^^^^^^^^^^^^^^^^^^^^^^^^^^^^^^^^^^^^^^^^^^^^^^^^^
  File "/home/walid/Bureau/oc_p13/venv/lib/python3.11/site-packages/sentry_sdk/integrations/django/views.py", line 84, in sentry_wrapped_callback
    return callback(request, *args, **kwargs)
           ^^^^^^^^^^^^^^^^^^^^^^^^^^^^^^^^^^
  File "/home/walid/Images/TEST-OC-P13/test_oc_p13/oc_lettings_site/views.py", line 57, in test_500
    raise ValueError("Test d'erreur 500")
ValueError: Test d'erreur 500
INFO 2024-02-06 11:19:29,761 views Affichage de la page d'accueil.
INFO 2024-02-06 11:19:29,789 views Affichage de la page d'accueil.
WARNING 2024-02-06 11:19:29,816 log Not Found: /chemin_inexistant/
ERROR 2024-02-06 11:19:29,842 views Erreur interne du serveur déclenchée.
ERROR 2024-02-06 11:19:29,858 log Internal Server Error: /test-500/
Traceback (most recent call last):
  File "/home/walid/Bureau/oc_p13/venv/lib/python3.11/site-packages/django/core/handlers/exception.py", line 55, in inner
    response = get_response(request)
               ^^^^^^^^^^^^^^^^^^^^^
  File "/home/walid/Bureau/oc_p13/venv/lib/python3.11/site-packages/django/core/handlers/base.py", line 197, in _get_response
    response = wrapped_callback(request, *callback_args, **callback_kwargs)
               ^^^^^^^^^^^^^^^^^^^^^^^^^^^^^^^^^^^^^^^^^^^^^^^^^^^^^^^^^^^^
  File "/home/walid/Bureau/oc_p13/venv/lib/python3.11/site-packages/sentry_sdk/integrations/django/views.py", line 84, in sentry_wrapped_callback
    return callback(request, *args, **kwargs)
           ^^^^^^^^^^^^^^^^^^^^^^^^^^^^^^^^^^
  File "/home/walid/Images/TEST-OC-P13/test_oc_p13/oc_lettings_site/views.py", line 57, in test_500
    raise ValueError("Test d'erreur 500")
ValueError: Test d'erreur 500
INFO 2024-02-06 11:19:30,251 views Quelque chose s'est produit avec l'utilisateur : testuser
INFO 2024-02-06 11:19:30,994 views Quelque chose s'est produit avec l'utilisateur : testuser
INFO 2024-02-06 11:19:33,878 views Affichage de la liste des profils.
INFO 2024-02-06 11:19:33,907 views Affichage de la liste des profils.
INFO 2024-02-06 11:19:33,935 views Affichage de la liste des profils.
INFO 2024-02-06 11:19:34,357 views Quelque chose s'est produit avec l'utilisateur : testuser
INFO 2024-02-06 11:19:34,382 views Quelque chose s'est produit avec l'utilisateur : testuser
INFO 2024-02-06 11:19:34,407 views Quelque chose s'est produit avec l'utilisateur : testuser
INFO 2024-02-06 11:25:06,540 views Affichage de la liste des lettings.
WARNING 2024-02-06 11:25:06,608 log Not Found: /une_url_inexistante/
ERROR 2024-02-06 11:25:06,633 views Erreur interne du serveur déclenchée.
ERROR 2024-02-06 11:25:06,682 log Internal Server Error: /test-500/
Traceback (most recent call last):
  File "/home/walid/Bureau/oc_p13/venv/lib/python3.11/site-packages/django/core/handlers/exception.py", line 55, in inner
    response = get_response(request)
               ^^^^^^^^^^^^^^^^^^^^^
  File "/home/walid/Bureau/oc_p13/venv/lib/python3.11/site-packages/django/core/handlers/base.py", line 197, in _get_response
    response = wrapped_callback(request, *callback_args, **callback_kwargs)
               ^^^^^^^^^^^^^^^^^^^^^^^^^^^^^^^^^^^^^^^^^^^^^^^^^^^^^^^^^^^^
  File "/home/walid/Bureau/oc_p13/venv/lib/python3.11/site-packages/sentry_sdk/integrations/django/views.py", line 84, in sentry_wrapped_callback
    return callback(request, *args, **kwargs)
           ^^^^^^^^^^^^^^^^^^^^^^^^^^^^^^^^^^
  File "/home/walid/Images/TEST-OC-P13/test_oc_p13/oc_lettings_site/views.py", line 57, in test_500
    raise ValueError("Test d'erreur 500")
ValueError: Test d'erreur 500
INFO 2024-02-06 11:25:06,708 views Affichage de la page d'accueil.
INFO 2024-02-06 11:25:06,736 views Affichage de la page d'accueil.
WARNING 2024-02-06 11:25:06,764 log Not Found: /chemin_inexistant/
ERROR 2024-02-06 11:25:06,791 views Erreur interne du serveur déclenchée.
ERROR 2024-02-06 11:25:06,807 log Internal Server Error: /test-500/
Traceback (most recent call last):
  File "/home/walid/Bureau/oc_p13/venv/lib/python3.11/site-packages/django/core/handlers/exception.py", line 55, in inner
    response = get_response(request)
               ^^^^^^^^^^^^^^^^^^^^^
  File "/home/walid/Bureau/oc_p13/venv/lib/python3.11/site-packages/django/core/handlers/base.py", line 197, in _get_response
    response = wrapped_callback(request, *callback_args, **callback_kwargs)
               ^^^^^^^^^^^^^^^^^^^^^^^^^^^^^^^^^^^^^^^^^^^^^^^^^^^^^^^^^^^^
  File "/home/walid/Bureau/oc_p13/venv/lib/python3.11/site-packages/sentry_sdk/integrations/django/views.py", line 84, in sentry_wrapped_callback
    return callback(request, *args, **kwargs)
           ^^^^^^^^^^^^^^^^^^^^^^^^^^^^^^^^^^
  File "/home/walid/Images/TEST-OC-P13/test_oc_p13/oc_lettings_site/views.py", line 57, in test_500
    raise ValueError("Test d'erreur 500")
ValueError: Test d'erreur 500
INFO 2024-02-06 11:25:07,209 views Quelque chose s'est produit avec l'utilisateur : testuser
INFO 2024-02-06 11:25:07,983 views Quelque chose s'est produit avec l'utilisateur : testuser
INFO 2024-02-06 11:25:10,892 views Affichage de la liste des profils.
INFO 2024-02-06 11:25:10,921 views Affichage de la liste des profils.
INFO 2024-02-06 11:25:10,950 views Affichage de la liste des profils.
INFO 2024-02-06 11:25:11,374 views Quelque chose s'est produit avec l'utilisateur : testuser
INFO 2024-02-06 11:25:11,400 views Quelque chose s'est produit avec l'utilisateur : testuser
INFO 2024-02-06 11:25:11,426 views Quelque chose s'est produit avec l'utilisateur : testuser
INFO 2024-02-06 11:35:06,062 views Affichage de la page d'accueil.
ERROR 2024-02-06 11:35:14,491 log Internal Server Error: /sentry-debug/
Traceback (most recent call last):
  File "/home/walid/Bureau/oc_p13/venv/lib/python3.11/site-packages/django/core/handlers/exception.py", line 55, in inner
    response = get_response(request)
               ^^^^^^^^^^^^^^^^^^^^^
  File "/home/walid/Bureau/oc_p13/venv/lib/python3.11/site-packages/django/core/handlers/base.py", line 197, in _get_response
    response = wrapped_callback(request, *callback_args, **callback_kwargs)
               ^^^^^^^^^^^^^^^^^^^^^^^^^^^^^^^^^^^^^^^^^^^^^^^^^^^^^^^^^^^^
  File "/home/walid/Bureau/oc_p13/venv/lib/python3.11/site-packages/sentry_sdk/integrations/django/views.py", line 84, in sentry_wrapped_callback
    return callback(request, *args, **kwargs)
           ^^^^^^^^^^^^^^^^^^^^^^^^^^^^^^^^^^
  File "/home/walid/Images/TEST-OC-P13/test_oc_p13/oc_lettings_site/urls.py", line 14, in trigger_error
    division_by_zero = 1 / 0
                       ~~^~~
ZeroDivisionError: division by zero
ERROR 2024-02-06 11:35:14,494 basehttp "GET /sentry-debug/ HTTP/1.1" 500 3421
INFO 2024-02-06 11:35:51,576 views Affichage de la liste des lettings.
WARNING 2024-02-06 11:35:51,648 log Not Found: /une_url_inexistante/
ERROR 2024-02-06 11:35:51,674 views Erreur interne du serveur déclenchée.
ERROR 2024-02-06 11:35:51,724 log Internal Server Error: /test-500/
Traceback (most recent call last):
  File "/home/walid/Bureau/oc_p13/venv/lib/python3.11/site-packages/django/core/handlers/exception.py", line 55, in inner
    response = get_response(request)
               ^^^^^^^^^^^^^^^^^^^^^
  File "/home/walid/Bureau/oc_p13/venv/lib/python3.11/site-packages/django/core/handlers/base.py", line 197, in _get_response
    response = wrapped_callback(request, *callback_args, **callback_kwargs)
               ^^^^^^^^^^^^^^^^^^^^^^^^^^^^^^^^^^^^^^^^^^^^^^^^^^^^^^^^^^^^
  File "/home/walid/Bureau/oc_p13/venv/lib/python3.11/site-packages/sentry_sdk/integrations/django/views.py", line 84, in sentry_wrapped_callback
    return callback(request, *args, **kwargs)
           ^^^^^^^^^^^^^^^^^^^^^^^^^^^^^^^^^^
  File "/home/walid/Images/TEST-OC-P13/test_oc_p13/oc_lettings_site/views.py", line 57, in test_500
    raise ValueError("Test d'erreur 500")
ValueError: Test d'erreur 500
INFO 2024-02-06 11:35:51,751 views Affichage de la page d'accueil.
INFO 2024-02-06 11:35:51,777 views Affichage de la page d'accueil.
WARNING 2024-02-06 11:35:51,803 log Not Found: /chemin_inexistant/
ERROR 2024-02-06 11:35:51,829 views Erreur interne du serveur déclenchée.
ERROR 2024-02-06 11:35:51,843 log Internal Server Error: /test-500/
Traceback (most recent call last):
  File "/home/walid/Bureau/oc_p13/venv/lib/python3.11/site-packages/django/core/handlers/exception.py", line 55, in inner
    response = get_response(request)
               ^^^^^^^^^^^^^^^^^^^^^
  File "/home/walid/Bureau/oc_p13/venv/lib/python3.11/site-packages/django/core/handlers/base.py", line 197, in _get_response
    response = wrapped_callback(request, *callback_args, **callback_kwargs)
               ^^^^^^^^^^^^^^^^^^^^^^^^^^^^^^^^^^^^^^^^^^^^^^^^^^^^^^^^^^^^
  File "/home/walid/Bureau/oc_p13/venv/lib/python3.11/site-packages/sentry_sdk/integrations/django/views.py", line 84, in sentry_wrapped_callback
    return callback(request, *args, **kwargs)
           ^^^^^^^^^^^^^^^^^^^^^^^^^^^^^^^^^^
  File "/home/walid/Images/TEST-OC-P13/test_oc_p13/oc_lettings_site/views.py", line 57, in test_500
    raise ValueError("Test d'erreur 500")
ValueError: Test d'erreur 500
INFO 2024-02-06 11:35:52,229 views Quelque chose s'est produit avec l'utilisateur : testuser
INFO 2024-02-06 11:35:52,976 views Quelque chose s'est produit avec l'utilisateur : testuser
INFO 2024-02-06 11:35:55,863 views Affichage de la liste des profils.
INFO 2024-02-06 11:35:55,892 views Affichage de la liste des profils.
INFO 2024-02-06 11:35:55,920 views Affichage de la liste des profils.
INFO 2024-02-06 11:35:56,338 views Quelque chose s'est produit avec l'utilisateur : testuser
INFO 2024-02-06 11:35:56,364 views Quelque chose s'est produit avec l'utilisateur : testuser
INFO 2024-02-06 11:35:56,391 views Quelque chose s'est produit avec l'utilisateur : testuser
INFO 2024-02-06 11:43:03,611 views Affichage de la liste des lettings.
WARNING 2024-02-06 11:43:03,693 log Not Found: /une_url_inexistante/
ERROR 2024-02-06 11:43:03,719 views Erreur interne du serveur déclenchée.
ERROR 2024-02-06 11:43:03,768 log Internal Server Error: /test-500/
Traceback (most recent call last):
  File "/home/walid/Bureau/oc_p13/venv/lib/python3.11/site-packages/django/core/handlers/exception.py", line 55, in inner
    response = get_response(request)
               ^^^^^^^^^^^^^^^^^^^^^
  File "/home/walid/Bureau/oc_p13/venv/lib/python3.11/site-packages/django/core/handlers/base.py", line 197, in _get_response
    response = wrapped_callback(request, *callback_args, **callback_kwargs)
               ^^^^^^^^^^^^^^^^^^^^^^^^^^^^^^^^^^^^^^^^^^^^^^^^^^^^^^^^^^^^
  File "/home/walid/Bureau/oc_p13/venv/lib/python3.11/site-packages/sentry_sdk/integrations/django/views.py", line 84, in sentry_wrapped_callback
    return callback(request, *args, **kwargs)
           ^^^^^^^^^^^^^^^^^^^^^^^^^^^^^^^^^^
  File "/home/walid/Images/TEST-OC-P13/test_oc_p13/oc_lettings_site/views.py", line 57, in test_500
    raise ValueError("Test d'erreur 500")
ValueError: Test d'erreur 500
INFO 2024-02-06 11:43:03,796 views Affichage de la page d'accueil.
INFO 2024-02-06 11:43:03,824 views Affichage de la page d'accueil.
WARNING 2024-02-06 11:43:03,852 log Not Found: /chemin_inexistant/
ERROR 2024-02-06 11:43:03,878 views Erreur interne du serveur déclenchée.
ERROR 2024-02-06 11:43:03,893 log Internal Server Error: /test-500/
Traceback (most recent call last):
  File "/home/walid/Bureau/oc_p13/venv/lib/python3.11/site-packages/django/core/handlers/exception.py", line 55, in inner
    response = get_response(request)
               ^^^^^^^^^^^^^^^^^^^^^
  File "/home/walid/Bureau/oc_p13/venv/lib/python3.11/site-packages/django/core/handlers/base.py", line 197, in _get_response
    response = wrapped_callback(request, *callback_args, **callback_kwargs)
               ^^^^^^^^^^^^^^^^^^^^^^^^^^^^^^^^^^^^^^^^^^^^^^^^^^^^^^^^^^^^
  File "/home/walid/Bureau/oc_p13/venv/lib/python3.11/site-packages/sentry_sdk/integrations/django/views.py", line 84, in sentry_wrapped_callback
    return callback(request, *args, **kwargs)
           ^^^^^^^^^^^^^^^^^^^^^^^^^^^^^^^^^^
  File "/home/walid/Images/TEST-OC-P13/test_oc_p13/oc_lettings_site/views.py", line 57, in test_500
    raise ValueError("Test d'erreur 500")
ValueError: Test d'erreur 500
INFO 2024-02-06 11:43:04,280 views Quelque chose s'est produit avec l'utilisateur : testuser
INFO 2024-02-06 11:43:05,028 views Quelque chose s'est produit avec l'utilisateur : testuser
INFO 2024-02-06 11:43:07,918 views Affichage de la liste des profils.
INFO 2024-02-06 11:43:07,948 views Affichage de la liste des profils.
INFO 2024-02-06 11:43:07,978 views Affichage de la liste des profils.
INFO 2024-02-06 11:43:08,394 views Quelque chose s'est produit avec l'utilisateur : testuser
INFO 2024-02-06 11:43:08,421 views Quelque chose s'est produit avec l'utilisateur : testuser
INFO 2024-02-06 11:43:08,449 views Quelque chose s'est produit avec l'utilisateur : testuser
INFO 2024-02-06 11:44:37,504 views Affichage de la liste des lettings.
WARNING 2024-02-06 11:44:37,573 log Not Found: /une_url_inexistante/
ERROR 2024-02-06 11:44:37,598 views Erreur interne du serveur déclenchée.
ERROR 2024-02-06 11:44:37,648 log Internal Server Error: /test-500/
Traceback (most recent call last):
  File "/home/walid/Bureau/oc_p13/venv/lib/python3.11/site-packages/django/core/handlers/exception.py", line 55, in inner
    response = get_response(request)
               ^^^^^^^^^^^^^^^^^^^^^
  File "/home/walid/Bureau/oc_p13/venv/lib/python3.11/site-packages/django/core/handlers/base.py", line 197, in _get_response
    response = wrapped_callback(request, *callback_args, **callback_kwargs)
               ^^^^^^^^^^^^^^^^^^^^^^^^^^^^^^^^^^^^^^^^^^^^^^^^^^^^^^^^^^^^
  File "/home/walid/Bureau/oc_p13/venv/lib/python3.11/site-packages/sentry_sdk/integrations/django/views.py", line 84, in sentry_wrapped_callback
    return callback(request, *args, **kwargs)
           ^^^^^^^^^^^^^^^^^^^^^^^^^^^^^^^^^^
  File "/home/walid/Images/TEST-OC-P13/test_oc_p13/oc_lettings_site/views.py", line 57, in test_500
    raise ValueError("Test d'erreur 500")
ValueError: Test d'erreur 500
INFO 2024-02-06 11:44:37,674 views Affichage de la page d'accueil.
INFO 2024-02-06 11:44:37,700 views Affichage de la page d'accueil.
WARNING 2024-02-06 11:44:37,726 log Not Found: /chemin_inexistant/
ERROR 2024-02-06 11:44:37,751 views Erreur interne du serveur déclenchée.
ERROR 2024-02-06 11:44:37,766 log Internal Server Error: /test-500/
Traceback (most recent call last):
  File "/home/walid/Bureau/oc_p13/venv/lib/python3.11/site-packages/django/core/handlers/exception.py", line 55, in inner
    response = get_response(request)
               ^^^^^^^^^^^^^^^^^^^^^
  File "/home/walid/Bureau/oc_p13/venv/lib/python3.11/site-packages/django/core/handlers/base.py", line 197, in _get_response
    response = wrapped_callback(request, *callback_args, **callback_kwargs)
               ^^^^^^^^^^^^^^^^^^^^^^^^^^^^^^^^^^^^^^^^^^^^^^^^^^^^^^^^^^^^
  File "/home/walid/Bureau/oc_p13/venv/lib/python3.11/site-packages/sentry_sdk/integrations/django/views.py", line 84, in sentry_wrapped_callback
    return callback(request, *args, **kwargs)
           ^^^^^^^^^^^^^^^^^^^^^^^^^^^^^^^^^^
  File "/home/walid/Images/TEST-OC-P13/test_oc_p13/oc_lettings_site/views.py", line 57, in test_500
    raise ValueError("Test d'erreur 500")
ValueError: Test d'erreur 500
INFO 2024-02-06 11:44:38,153 views Quelque chose s'est produit avec l'utilisateur : testuser
INFO 2024-02-06 11:44:38,900 views Quelque chose s'est produit avec l'utilisateur : testuser
INFO 2024-02-06 11:44:41,792 views Affichage de la liste des profils.
INFO 2024-02-06 11:44:41,820 views Affichage de la liste des profils.
INFO 2024-02-06 11:44:41,849 views Affichage de la liste des profils.
INFO 2024-02-06 11:44:42,265 views Quelque chose s'est produit avec l'utilisateur : testuser
INFO 2024-02-06 11:44:42,290 views Quelque chose s'est produit avec l'utilisateur : testuser
INFO 2024-02-06 11:44:42,316 views Quelque chose s'est produit avec l'utilisateur : testuser
INFO 2024-02-06 11:56:40,416 views Affichage de la page d'accueil.
INFO 2024-02-06 11:56:42,183 views Affichage de la liste des profils.
INFO 2024-02-06 11:56:43,306 views Quelque chose s'est produit avec l'utilisateur : AirWow
INFO 2024-02-06 11:56:44,824 views Affichage de la liste des lettings.
INFO 2024-02-06 12:08:34,717 views Affichage de la liste des lettings.
WARNING 2024-02-06 12:08:34,787 log Not Found: /une_url_inexistante/
ERROR 2024-02-06 12:08:34,812 views Erreur interne du serveur déclenchée.
ERROR 2024-02-06 12:08:34,880 log Internal Server Error: /test-500/
Traceback (most recent call last):
  File "/home/walid/Bureau/oc_p13/venv/lib/python3.11/site-packages/django/core/handlers/exception.py", line 55, in inner
    response = get_response(request)
               ^^^^^^^^^^^^^^^^^^^^^
  File "/home/walid/Bureau/oc_p13/venv/lib/python3.11/site-packages/django/core/handlers/base.py", line 197, in _get_response
    response = wrapped_callback(request, *callback_args, **callback_kwargs)
               ^^^^^^^^^^^^^^^^^^^^^^^^^^^^^^^^^^^^^^^^^^^^^^^^^^^^^^^^^^^^
  File "/home/walid/Bureau/oc_p13/venv/lib/python3.11/site-packages/sentry_sdk/integrations/django/views.py", line 84, in sentry_wrapped_callback
    return callback(request, *args, **kwargs)
           ^^^^^^^^^^^^^^^^^^^^^^^^^^^^^^^^^^
  File "/home/walid/Images/TEST-OC-P13/test_oc_p13/oc_lettings_site/views.py", line 57, in test_500
    raise ValueError("Test d'erreur 500")
ValueError: Test d'erreur 500
INFO 2024-02-06 12:08:34,906 views Affichage de la page d'accueil.
INFO 2024-02-06 12:08:34,935 views Affichage de la page d'accueil.
WARNING 2024-02-06 12:08:34,965 log Not Found: /chemin_inexistant/
ERROR 2024-02-06 12:08:34,992 views Erreur interne du serveur déclenchée.
ERROR 2024-02-06 12:08:35,010 log Internal Server Error: /test-500/
Traceback (most recent call last):
  File "/home/walid/Bureau/oc_p13/venv/lib/python3.11/site-packages/django/core/handlers/exception.py", line 55, in inner
    response = get_response(request)
               ^^^^^^^^^^^^^^^^^^^^^
  File "/home/walid/Bureau/oc_p13/venv/lib/python3.11/site-packages/django/core/handlers/base.py", line 197, in _get_response
    response = wrapped_callback(request, *callback_args, **callback_kwargs)
               ^^^^^^^^^^^^^^^^^^^^^^^^^^^^^^^^^^^^^^^^^^^^^^^^^^^^^^^^^^^^
  File "/home/walid/Bureau/oc_p13/venv/lib/python3.11/site-packages/sentry_sdk/integrations/django/views.py", line 84, in sentry_wrapped_callback
    return callback(request, *args, **kwargs)
           ^^^^^^^^^^^^^^^^^^^^^^^^^^^^^^^^^^
  File "/home/walid/Images/TEST-OC-P13/test_oc_p13/oc_lettings_site/views.py", line 57, in test_500
    raise ValueError("Test d'erreur 500")
ValueError: Test d'erreur 500
INFO 2024-02-06 12:08:35,406 views Quelque chose s'est produit avec l'utilisateur : testuser
INFO 2024-02-06 12:08:36,162 views Quelque chose s'est produit avec l'utilisateur : testuser
INFO 2024-02-06 12:08:39,078 views Affichage de la liste des profils.
INFO 2024-02-06 12:08:39,106 views Affichage de la liste des profils.
INFO 2024-02-06 12:08:39,134 views Affichage de la liste des profils.
INFO 2024-02-06 12:08:39,548 views Quelque chose s'est produit avec l'utilisateur : testuser
INFO 2024-02-06 12:08:39,573 views Quelque chose s'est produit avec l'utilisateur : testuser
INFO 2024-02-06 12:08:39,599 views Quelque chose s'est produit avec l'utilisateur : testuser
INFO 2024-02-06 12:11:28,202 views Affichage de la liste des lettings.
WARNING 2024-02-06 12:11:28,273 log Not Found: /une_url_inexistante/
ERROR 2024-02-06 12:11:28,298 views Erreur interne du serveur déclenchée.
ERROR 2024-02-06 12:11:28,348 log Internal Server Error: /test-500/
Traceback (most recent call last):
  File "/home/walid/Bureau/oc_p13/venv/lib/python3.11/site-packages/django/core/handlers/exception.py", line 55, in inner
    response = get_response(request)
               ^^^^^^^^^^^^^^^^^^^^^
  File "/home/walid/Bureau/oc_p13/venv/lib/python3.11/site-packages/django/core/handlers/base.py", line 197, in _get_response
    response = wrapped_callback(request, *callback_args, **callback_kwargs)
               ^^^^^^^^^^^^^^^^^^^^^^^^^^^^^^^^^^^^^^^^^^^^^^^^^^^^^^^^^^^^
  File "/home/walid/Bureau/oc_p13/venv/lib/python3.11/site-packages/sentry_sdk/integrations/django/views.py", line 84, in sentry_wrapped_callback
    return callback(request, *args, **kwargs)
           ^^^^^^^^^^^^^^^^^^^^^^^^^^^^^^^^^^
  File "/home/walid/Images/TEST-OC-P13/test_oc_p13/oc_lettings_site/views.py", line 57, in test_500
    raise ValueError("Test d'erreur 500")
ValueError: Test d'erreur 500
INFO 2024-02-06 12:11:28,374 views Affichage de la page d'accueil.
INFO 2024-02-06 12:11:28,401 views Affichage de la page d'accueil.
WARNING 2024-02-06 12:11:28,426 log Not Found: /chemin_inexistant/
ERROR 2024-02-06 12:11:28,452 views Erreur interne du serveur déclenchée.
ERROR 2024-02-06 12:11:28,466 log Internal Server Error: /test-500/
Traceback (most recent call last):
  File "/home/walid/Bureau/oc_p13/venv/lib/python3.11/site-packages/django/core/handlers/exception.py", line 55, in inner
    response = get_response(request)
               ^^^^^^^^^^^^^^^^^^^^^
  File "/home/walid/Bureau/oc_p13/venv/lib/python3.11/site-packages/django/core/handlers/base.py", line 197, in _get_response
    response = wrapped_callback(request, *callback_args, **callback_kwargs)
               ^^^^^^^^^^^^^^^^^^^^^^^^^^^^^^^^^^^^^^^^^^^^^^^^^^^^^^^^^^^^
  File "/home/walid/Bureau/oc_p13/venv/lib/python3.11/site-packages/sentry_sdk/integrations/django/views.py", line 84, in sentry_wrapped_callback
    return callback(request, *args, **kwargs)
           ^^^^^^^^^^^^^^^^^^^^^^^^^^^^^^^^^^
  File "/home/walid/Images/TEST-OC-P13/test_oc_p13/oc_lettings_site/views.py", line 57, in test_500
    raise ValueError("Test d'erreur 500")
ValueError: Test d'erreur 500
INFO 2024-02-06 12:11:28,857 views Quelque chose s'est produit avec l'utilisateur : testuser
INFO 2024-02-06 12:11:29,603 views Quelque chose s'est produit avec l'utilisateur : testuser
INFO 2024-02-06 12:11:32,505 views Affichage de la liste des profils.
INFO 2024-02-06 12:11:32,533 views Affichage de la liste des profils.
INFO 2024-02-06 12:11:32,561 views Affichage de la liste des profils.
INFO 2024-02-06 12:11:32,983 views Quelque chose s'est produit avec l'utilisateur : testuser
INFO 2024-02-06 12:11:33,008 views Quelque chose s'est produit avec l'utilisateur : testuser
INFO 2024-02-06 12:11:33,034 views Quelque chose s'est produit avec l'utilisateur : testuser
INFO 2024-02-06 12:52:01,437 views Affichage de la page d'accueil.
INFO 2024-02-06 12:52:55,404 views Affichage de la liste des lettings.
WARNING 2024-02-06 12:52:55,474 log Not Found: /une_url_inexistante/
ERROR 2024-02-06 12:52:55,500 views Erreur interne du serveur déclenchée.
ERROR 2024-02-06 12:52:55,549 log Internal Server Error: /test-500/
Traceback (most recent call last):
  File "/home/walid/Bureau/oc_p13/venv/lib/python3.11/site-packages/django/core/handlers/exception.py", line 55, in inner
    response = get_response(request)
               ^^^^^^^^^^^^^^^^^^^^^
  File "/home/walid/Bureau/oc_p13/venv/lib/python3.11/site-packages/django/core/handlers/base.py", line 197, in _get_response
    response = wrapped_callback(request, *callback_args, **callback_kwargs)
               ^^^^^^^^^^^^^^^^^^^^^^^^^^^^^^^^^^^^^^^^^^^^^^^^^^^^^^^^^^^^
  File "/home/walid/Bureau/oc_p13/venv/lib/python3.11/site-packages/sentry_sdk/integrations/django/views.py", line 84, in sentry_wrapped_callback
    return callback(request, *args, **kwargs)
           ^^^^^^^^^^^^^^^^^^^^^^^^^^^^^^^^^^
  File "/home/walid/Images/TEST-OC-P13/test_oc_p13/oc_lettings_site/views.py", line 57, in test_500
    raise ValueError("Test d'erreur 500")
ValueError: Test d'erreur 500
INFO 2024-02-06 12:52:55,576 views Affichage de la page d'accueil.
INFO 2024-02-06 12:52:55,602 views Affichage de la page d'accueil.
WARNING 2024-02-06 12:52:55,628 log Not Found: /chemin_inexistant/
ERROR 2024-02-06 12:52:55,654 views Erreur interne du serveur déclenchée.
ERROR 2024-02-06 12:52:55,670 log Internal Server Error: /test-500/
Traceback (most recent call last):
  File "/home/walid/Bureau/oc_p13/venv/lib/python3.11/site-packages/django/core/handlers/exception.py", line 55, in inner
    response = get_response(request)
               ^^^^^^^^^^^^^^^^^^^^^
  File "/home/walid/Bureau/oc_p13/venv/lib/python3.11/site-packages/django/core/handlers/base.py", line 197, in _get_response
    response = wrapped_callback(request, *callback_args, **callback_kwargs)
               ^^^^^^^^^^^^^^^^^^^^^^^^^^^^^^^^^^^^^^^^^^^^^^^^^^^^^^^^^^^^
  File "/home/walid/Bureau/oc_p13/venv/lib/python3.11/site-packages/sentry_sdk/integrations/django/views.py", line 84, in sentry_wrapped_callback
    return callback(request, *args, **kwargs)
           ^^^^^^^^^^^^^^^^^^^^^^^^^^^^^^^^^^
  File "/home/walid/Images/TEST-OC-P13/test_oc_p13/oc_lettings_site/views.py", line 57, in test_500
    raise ValueError("Test d'erreur 500")
ValueError: Test d'erreur 500
INFO 2024-02-06 12:52:56,060 views Quelque chose s'est produit avec l'utilisateur : testuser
INFO 2024-02-06 12:52:56,819 views Quelque chose s'est produit avec l'utilisateur : testuser
INFO 2024-02-06 12:52:59,729 views Affichage de la liste des profils.
INFO 2024-02-06 12:52:59,758 views Affichage de la liste des profils.
INFO 2024-02-06 12:52:59,786 views Affichage de la liste des profils.
INFO 2024-02-06 12:53:00,203 views Quelque chose s'est produit avec l'utilisateur : testuser
INFO 2024-02-06 12:53:00,229 views Quelque chose s'est produit avec l'utilisateur : testuser
INFO 2024-02-06 12:53:00,255 views Quelque chose s'est produit avec l'utilisateur : testuser
ERROR 2024-02-06 13:17:43,069 basehttp You're accessing the development server over HTTPS, but it only supports HTTP.
ERROR 2024-02-06 13:17:43,069 basehttp You're accessing the development server over HTTPS, but it only supports HTTP.
ERROR 2024-02-06 13:17:45,890 exception Invalid HTTP_HOST header: '0.0.0.0:8000'. You may need to add '0.0.0.0' to ALLOWED_HOSTS.
Traceback (most recent call last):
  File "/home/walid/Bureau/oc_p13/venv/lib/python3.11/site-packages/django/core/handlers/exception.py", line 55, in inner
    response = get_response(request)
               ^^^^^^^^^^^^^^^^^^^^^
  File "/home/walid/Bureau/oc_p13/venv/lib/python3.11/site-packages/sentry_sdk/integrations/django/middleware.py", line 175, in __call__
    return f(*args, **kwargs)
           ^^^^^^^^^^^^^^^^^^
  File "/home/walid/Bureau/oc_p13/venv/lib/python3.11/site-packages/django/utils/deprecation.py", line 133, in __call__
    response = self.process_request(request)
               ^^^^^^^^^^^^^^^^^^^^^^^^^^^^^
  File "/home/walid/Bureau/oc_p13/venv/lib/python3.11/site-packages/django/middleware/common.py", line 48, in process_request
    host = request.get_host()
           ^^^^^^^^^^^^^^^^^^
  File "/home/walid/Bureau/oc_p13/venv/lib/python3.11/site-packages/django/http/request.py", line 151, in get_host
    raise DisallowedHost(msg)
django.core.exceptions.DisallowedHost: Invalid HTTP_HOST header: '0.0.0.0:8000'. You may need to add '0.0.0.0' to ALLOWED_HOSTS.
WARNING 2024-02-06 13:17:45,933 log Bad Request: /
WARNING 2024-02-06 13:17:45,934 basehttp "GET / HTTP/1.1" 400 143
ERROR 2024-02-06 13:17:46,186 exception Invalid HTTP_HOST header: '0.0.0.0:8000'. You may need to add '0.0.0.0' to ALLOWED_HOSTS.
Traceback (most recent call last):
  File "/home/walid/Bureau/oc_p13/venv/lib/python3.11/site-packages/django/core/handlers/exception.py", line 55, in inner
    response = get_response(request)
               ^^^^^^^^^^^^^^^^^^^^^
  File "/home/walid/Bureau/oc_p13/venv/lib/python3.11/site-packages/sentry_sdk/integrations/django/middleware.py", line 175, in __call__
    return f(*args, **kwargs)
           ^^^^^^^^^^^^^^^^^^
  File "/home/walid/Bureau/oc_p13/venv/lib/python3.11/site-packages/django/utils/deprecation.py", line 133, in __call__
    response = self.process_request(request)
               ^^^^^^^^^^^^^^^^^^^^^^^^^^^^^
  File "/home/walid/Bureau/oc_p13/venv/lib/python3.11/site-packages/django/middleware/common.py", line 48, in process_request
    host = request.get_host()
           ^^^^^^^^^^^^^^^^^^
  File "/home/walid/Bureau/oc_p13/venv/lib/python3.11/site-packages/django/http/request.py", line 151, in get_host
    raise DisallowedHost(msg)
django.core.exceptions.DisallowedHost: Invalid HTTP_HOST header: '0.0.0.0:8000'. You may need to add '0.0.0.0' to ALLOWED_HOSTS.
WARNING 2024-02-06 13:17:46,189 log Bad Request: /favicon.ico
WARNING 2024-02-06 13:17:46,190 basehttp "GET /favicon.ico HTTP/1.1" 400 143
